{
 "cells": [
  {
   "cell_type": "code",
   "execution_count": 16,
   "metadata": {},
   "outputs": [],
   "source": [
    "# TensorFlow and tf.keras\n",
    "import tensorflow as tf\n",
    "from tensorflow import keras\n",
    "from keras import optimizers\n",
    "\n",
    "# Helper libraries\n",
    "import numpy as np\n",
    "import matplotlib.pyplot as plt\n",
    "\n",
    "fashion_mnist = keras.datasets.fashion_mnist\n",
    "\n",
    "(train_images, train_labels), (test_images, test_labels) = fashion_mnist.load_data()\n",
    "\n",
    "x_train = x_train / 255.0\n",
    "x_test = x_test / 255.0\n",
    "\n",
    "# plt.imshow(x_train[0])\n",
    "# plt.show"
   ]
  },
  {
   "cell_type": "code",
   "execution_count": 20,
   "metadata": {},
   "outputs": [],
   "source": [
    "model = keras.Sequential([\n",
    "    keras.layers.Flatten(input_shape=(28, 28)),\n",
    "    keras.layers.Dense(128, activation='relu'),\n",
    "#     keras.layers.Dense()\n",
    "    keras.layers.Dense(10, activation='softmax')\n",
    "])"
   ]
  },
  {
   "cell_type": "code",
   "execution_count": 29,
   "metadata": {},
   "outputs": [
    {
     "ename": "SyntaxError",
     "evalue": "positional argument follows keyword argument (<ipython-input-29-0f93cd20929e>, line 2)",
     "output_type": "error",
     "traceback": [
      "\u001b[0;36m  File \u001b[0;32m\"<ipython-input-29-0f93cd20929e>\"\u001b[0;36m, line \u001b[0;32m2\u001b[0m\n\u001b[0;31m    optimizers.SGD(lr=0.01),\u001b[0m\n\u001b[0m    ^\u001b[0m\n\u001b[0;31mSyntaxError\u001b[0m\u001b[0;31m:\u001b[0m positional argument follows keyword argument\n"
     ]
    }
   ],
   "source": [
    "model.compile(loss='categorical_crossentropy',\n",
    "    optimizers.SGD(lr=0.01),\n",
    "    metrics=['accuracy'])"
   ]
  },
  {
   "cell_type": "code",
   "execution_count": 23,
   "metadata": {},
   "outputs": [
    {
     "ename": "ValueError",
     "evalue": "Error when checking target: expected dense_5 to have shape (10,) but got array with shape (1,)",
     "output_type": "error",
     "traceback": [
      "\u001b[0;31m---------------------------------------------------------------------------\u001b[0m",
      "\u001b[0;31mValueError\u001b[0m                                Traceback (most recent call last)",
      "\u001b[0;32m<ipython-input-23-b4de695e0465>\u001b[0m in \u001b[0;36m<module>\u001b[0;34m\u001b[0m\n\u001b[0;32m----> 1\u001b[0;31m \u001b[0mmodel\u001b[0m\u001b[0;34m.\u001b[0m\u001b[0mfit\u001b[0m\u001b[0;34m(\u001b[0m\u001b[0mtrain_images\u001b[0m\u001b[0;34m,\u001b[0m \u001b[0mtrain_labels\u001b[0m\u001b[0;34m,\u001b[0m \u001b[0mepochs\u001b[0m\u001b[0;34m=\u001b[0m\u001b[0;36m5\u001b[0m\u001b[0;34m)\u001b[0m\u001b[0;34m\u001b[0m\u001b[0m\n\u001b[0m",
      "\u001b[0;32m~/Virtual_Environments/main_env/lib/python3.5/site-packages/tensorflow/python/keras/engine/training.py\u001b[0m in \u001b[0;36mfit\u001b[0;34m(self, x, y, batch_size, epochs, verbose, callbacks, validation_split, validation_data, shuffle, class_weight, sample_weight, initial_epoch, steps_per_epoch, validation_steps, max_queue_size, workers, use_multiprocessing, **kwargs)\u001b[0m\n\u001b[1;32m   1534\u001b[0m         \u001b[0msteps_name\u001b[0m\u001b[0;34m=\u001b[0m\u001b[0;34m'steps_per_epoch'\u001b[0m\u001b[0;34m,\u001b[0m\u001b[0;34m\u001b[0m\u001b[0m\n\u001b[1;32m   1535\u001b[0m         \u001b[0msteps\u001b[0m\u001b[0;34m=\u001b[0m\u001b[0msteps_per_epoch\u001b[0m\u001b[0;34m,\u001b[0m\u001b[0;34m\u001b[0m\u001b[0m\n\u001b[0;32m-> 1536\u001b[0;31m         validation_split=validation_split)\n\u001b[0m\u001b[1;32m   1537\u001b[0m \u001b[0;34m\u001b[0m\u001b[0m\n\u001b[1;32m   1538\u001b[0m     \u001b[0;31m# Prepare validation data.\u001b[0m\u001b[0;34m\u001b[0m\u001b[0;34m\u001b[0m\u001b[0m\n",
      "\u001b[0;32m~/Virtual_Environments/main_env/lib/python3.5/site-packages/tensorflow/python/keras/engine/training.py\u001b[0m in \u001b[0;36m_standardize_user_data\u001b[0;34m(self, x, y, sample_weight, class_weight, batch_size, check_steps, steps_name, steps, validation_split)\u001b[0m\n\u001b[1;32m    990\u001b[0m         \u001b[0mx\u001b[0m\u001b[0;34m,\u001b[0m \u001b[0my\u001b[0m\u001b[0;34m,\u001b[0m \u001b[0msample_weight\u001b[0m \u001b[0;34m=\u001b[0m \u001b[0mnext_element\u001b[0m\u001b[0;34m\u001b[0m\u001b[0m\n\u001b[1;32m    991\u001b[0m     x, y, sample_weights = self._standardize_weights(x, y, sample_weight,\n\u001b[0;32m--> 992\u001b[0;31m                                                      class_weight, batch_size)\n\u001b[0m\u001b[1;32m    993\u001b[0m     \u001b[0;32mreturn\u001b[0m \u001b[0mx\u001b[0m\u001b[0;34m,\u001b[0m \u001b[0my\u001b[0m\u001b[0;34m,\u001b[0m \u001b[0msample_weights\u001b[0m\u001b[0;34m\u001b[0m\u001b[0m\n\u001b[1;32m    994\u001b[0m \u001b[0;34m\u001b[0m\u001b[0m\n",
      "\u001b[0;32m~/Virtual_Environments/main_env/lib/python3.5/site-packages/tensorflow/python/keras/engine/training.py\u001b[0m in \u001b[0;36m_standardize_weights\u001b[0;34m(self, x, y, sample_weight, class_weight, batch_size)\u001b[0m\n\u001b[1;32m   1152\u001b[0m           \u001b[0mfeed_output_shapes\u001b[0m\u001b[0;34m,\u001b[0m\u001b[0;34m\u001b[0m\u001b[0m\n\u001b[1;32m   1153\u001b[0m           \u001b[0mcheck_batch_axis\u001b[0m\u001b[0;34m=\u001b[0m\u001b[0;32mFalse\u001b[0m\u001b[0;34m,\u001b[0m  \u001b[0;31m# Don't enforce the batch size.\u001b[0m\u001b[0;34m\u001b[0m\u001b[0m\n\u001b[0;32m-> 1154\u001b[0;31m           exception_prefix='target')\n\u001b[0m\u001b[1;32m   1155\u001b[0m \u001b[0;34m\u001b[0m\u001b[0m\n\u001b[1;32m   1156\u001b[0m       \u001b[0;31m# Generate sample-wise weight values given the `sample_weight` and\u001b[0m\u001b[0;34m\u001b[0m\u001b[0;34m\u001b[0m\u001b[0m\n",
      "\u001b[0;32m~/Virtual_Environments/main_env/lib/python3.5/site-packages/tensorflow/python/keras/engine/training_utils.py\u001b[0m in \u001b[0;36mstandardize_input_data\u001b[0;34m(data, names, shapes, check_batch_axis, exception_prefix)\u001b[0m\n\u001b[1;32m    330\u001b[0m                 \u001b[0;34m'Error when checking '\u001b[0m \u001b[0;34m+\u001b[0m \u001b[0mexception_prefix\u001b[0m \u001b[0;34m+\u001b[0m \u001b[0;34m': expected '\u001b[0m \u001b[0;34m+\u001b[0m\u001b[0;34m\u001b[0m\u001b[0m\n\u001b[1;32m    331\u001b[0m                 \u001b[0mnames\u001b[0m\u001b[0;34m[\u001b[0m\u001b[0mi\u001b[0m\u001b[0;34m]\u001b[0m \u001b[0;34m+\u001b[0m \u001b[0;34m' to have shape '\u001b[0m \u001b[0;34m+\u001b[0m \u001b[0mstr\u001b[0m\u001b[0;34m(\u001b[0m\u001b[0mshape\u001b[0m\u001b[0;34m)\u001b[0m \u001b[0;34m+\u001b[0m\u001b[0;34m\u001b[0m\u001b[0m\n\u001b[0;32m--> 332\u001b[0;31m                 ' but got array with shape ' + str(data_shape))\n\u001b[0m\u001b[1;32m    333\u001b[0m   \u001b[0;32mreturn\u001b[0m \u001b[0mdata\u001b[0m\u001b[0;34m\u001b[0m\u001b[0m\n\u001b[1;32m    334\u001b[0m \u001b[0;34m\u001b[0m\u001b[0m\n",
      "\u001b[0;31mValueError\u001b[0m: Error when checking target: expected dense_5 to have shape (10,) but got array with shape (1,)"
     ]
    }
   ],
   "source": [
    "model.fit(train_images, train_labels, epochs=5)"
   ]
  }
 ],
 "metadata": {
  "kernelspec": {
   "display_name": "main_env",
   "language": "python",
   "name": "main_env"
  },
  "language_info": {
   "codemirror_mode": {
    "name": "ipython",
    "version": 3
   },
   "file_extension": ".py",
   "mimetype": "text/x-python",
   "name": "python",
   "nbconvert_exporter": "python",
   "pygments_lexer": "ipython3",
   "version": "3.5.2"
  }
 },
 "nbformat": 4,
 "nbformat_minor": 2
}
